Workbook

Sheet Sheet1
B3: NCF
B4: Keterangan | C4: Tahun 0 | D4: Tahun 1 | E4: Tahun 2 | F4: Tahun 3 | G4: Tahun 4 | H4: Tahun 5
B5: Investasi Awal | C5: =C19 -> 190585000
B6: Cash Inflow/CIF | D6: =Sheet2!C20 -> 913500000 | E6: =Sheet2!D20 -> 1263600000 | F6: =Sheet2!E20 -> 1680600000 | G6: =Sheet2!F20 -> 2115300000 | H6: =Sheet2!G20 -> 2702100000
B7: Cash Outflow/COF(-) | D7: =Sheet2!C173 -> 416386000 | E7: =Sheet2!D173 -> 472371400 | F7: =Sheet2!E173 -> 550098352 | G7: =Sheet2!F173 -> 6.5112595e+08 | H7: =Sheet2!G173 -> 7.998393e+08
B8: NCF = EAT | D8: =D6-D7 -> 497114000 | E8: =E6-E7 -> 791228600 | F8: =F6-F7 -> 1130501648 | G8: =G6-G7 -> 1.4641741e+09 | H8: =H6-H7 -> 1.9022607e+09
B9: Depresiasi (+) | D9: =$D$68 -> 29702000 | E9: =$D$68 -> 29702000 | F9: =$D$68 -> 29702000 | G9: =$D$68 -> 29702000 | H9: =$D$68 -> 29702000
B10: Proceed | D10: =D8-D9 -> 467412000 | E10: =E8-E9 -> 761526600 | F10: =F8-F9 -> 1100799648 | G10: =G8-G9 -> 1.4344721e+09 | H10: =H8-H9 -> 1.8725587e+09
B13: Initial Outlay
B14: Aktiva Tetap | C14: =F66 -> 148510000
B15: Biaya Sewa | C15: =E72 -> 40000000
B16: Biaya Amdal | C16: =F78 -> 325000
B17: Biaya Survey | C17: =F85 -> 750000
B18: Biaya Promosi | C18: =F90 -> 1000000
B19: Total | C19: =SUM(C14:C18) -> 190585000
B22: AKTIVA TETAP
B23: No. | C23: Keterangan | D23: Jumlah | E23: Harga Satuan | F23: Total
B24: 1 | C24: Meja kayu | D24: 6 | E24: 1200000 | F24: =E24*D24 -> 7200000
B25: 2 | C25: Kursi kayu | D25: 24 | E25: 250000 | F25: =E25*D25 -> 6000000
B26: 3 | C26: Etalase produksi | D26: 2 | E26: 2500000 | F26: =E26*D26 -> 5000000
B27: 4 | C27: Loyang bulat | D27: 5 | E27: 150000 | F27: =E27*D27 -> 750000
B28: 5 | C28: Loyang hati | D28: 5 | E28: 150000 | F28: =E28*D28 -> 750000
B29: 6 | C29: Loyang kotak | D29: 5 | E29: 150000 | F29: =E29*D29 -> 750000
B30: 7 | C30: Loyang small | D30: 5 | E30: 70000 | F30: =E30*D30 -> 350000
B31: 8 | C31: Loyang Medium | D31: 5 | E31: 100000 | F31: =E31*D31 -> 500000
B32: 9 | C32: Loyang Large | D32: 5 | E32: 120000 | F32: =E32*D32 -> 600000
B33: 10 | C33: Loyang Jumbo | D33: 5 | E33: 150000 | F33: =E33*D33 -> 750000
B34: 11 | C34: Mesin adonan | D34: 5 | E34: 5000000 | F34: =E34*D34 -> 25000000
B35: 12 | C35: Pisau potong | D35: 10 | E35: 35000 | F35: =E35*D35 -> 350000
... B65: 42 | C65: Kabel Panjang | D65: 5 | E65: 100000 | F65: =E65*D65 -> 500000
B66: Total Biaya | F66: =SUM(F24:F61) -> 148510000
B68: Depresiasi (20%) | D68: =F66*20% -> 29702000
B70: BIAYA SEWA
B71: No | C71: Keterangan | D71: Jangka Waktu (/tahun) | E71: Harga Sewa per tahun | F71: Harga Sewa per bulan
B72: 1 | C72: Biaya Sewa Tempat | D72: 5 | E72: 40000000 | F72: =(D72*E72)/60 -> 3333333.3
B73: Total Biaya | F73: =F72 -> 3333333.3
B75: BIAYA AMDAL
B76: No | C76: Keterangan | D76: Jumlah | E76: Harga satuan | F76: Total
B77: 1 | C77: Tempat sampah | D77: 5 | E77: 65000 | F77: =E77*D77 -> 325000
B78: Total Biaya | F78: =SUM(F77:F77) -> 325000
...

Sheet Sheet2
B2: CASH INFLOW
B3: Cash Inflow | C3: Tahun 1 | D3: Tahun 2 | E3: Tahun 3 | F3: Tahun 4 | G3: Tahun 5
B4: Penjualan Martabak
B5: Penjualan Martabak Manis
B6: Martabak Small | C6: =C149 -> 45000000 | D6: =D149 -> 66300000 | E6: =E149 -> 84000000 | F6: =F149 -> 110400000 | G6: =G149 -> 129600000
B7: Martabak Regular | C7: =C150 -> 84000000 | D7: =D150 -> 117000000 | E7: =E150 -> 158400000 | F7: =F150 -> 210000000 | G7: =G150 -> 278400000
B8: Martabak Large | C8: =C151 -> 81000000 | D8: =D151 -> 120000000 | E8: =E151 -> 1.68e+08 | F8: =F151 -> 211200000 | G8: =G151 -> 288600000
B9: Martabak Jumbo | C9: =C152 -> 135000000 | D9: =D152 -> 1.815e+08 | E9: =E152 -> 241800000 | F9: =F152 -> 298200000 | G9: =G152 -> 369000000
B10: Penjualan Martabak Asin
B11: Martabak Telur | C11: =C154 -> 94500000 | D11: =D154 -> 140400000 | E11: =E154 -> 184800000 | F11: =F154 -> 225000000 | G11: =G154 -> 278400000
B12: Martabak Daging Ayam | C12: =C155 -> 96000000 | D12: =D155 -> 132000000 | E12: =E155 -> 180000000 | F12: =F155 -> 239400000 | G12: =G155 -> 316800000
B13: Martabak Daging Kambing | C13: =C156 -> 135000000 | D13: =D156 -> 180000000 | E13: =E156 -> 2.352e+08 | F13: =F156 -> 288000000 | G13: =G156 -> 377400000
B14: Martabak Daging Sapi | C14: =C157 -> 165000000 | D14: =D157 -> 2.145e+08 | E14: =E157 -> 279000000 | F14: =F157 -> 340800000 | G14: =G157 -> 418200000
B15: Penjualan Minuman
B16: Penjualan Es Jeruk | C16: =C159 -> 24000000 | D16: =D159 -> 36300000 | E16: =E159 -> 50700000 | F16: =F159 -> 67500000 | G16: =G159 -> 86400000
B17: Penjualan Es Teh Manis | C17: =C160 -> 21000000 | D17: =D160 -> 28800000 | E17: =E160 -> 37800000 | F17: =F160 -> 52800000 | G17: =G160 -> 66300000
B18: Penjualan Es The Tawar | C18: =C161 -> 18000000 | D18: =D161 -> 25200000 | E18: =E161 -> 33600000 | F18: =F161 -> 38400000 | G18: =G161 -> 51000000
B19: Penjualan Air Mineral | C19: =C162 -> 15000000 | D19: =D162 -> 21600000 | E19: =E162 -> 27300000 | F19: =F162 -> 33600000 | G19: =G162 -> 42000000
B20: Total | C20: =SUM(C6:C19) -> 913500000 | D20: =SUM(D6:D19) -> 1263600000 | E20: =SUM(E6:E19) -> 1680600000 | F20: =SUM(F6:F19) -> 2115300000 | G20: =SUM(G6:G19) -> 2702100000
B23: Target Penjualan Harian | C23: Tahun 1 | D23: Tahun 2 | E23: Tahun 3 | F23: Tahun 4 | G23: Tahun 5
B24: Penjualan Martabak
B25: Penjualan Martabak Manis
B26: Martabak Small | C26: 10 | D26: =C26+3 -> 13 | E26: =D26+1 -> 14 | F26: =E26+2 -> 16 | G26: =F26 -> 16
B27: Martabak Regular | C27: 8 | D27: =C27+2 -> 10 | E27: =D27+2 -> 12 | F27: =E27+2 -> 14 | G27: =F27+2 -> 16
B28: Martabak Large | C28: 6 | D28: =C28+2 -> 8 | E28: =D28+2 -> 10 | F28: =E28+1 -> 11 | G28: =F28+2 -> 13
B29: Martabak Jumbo | C29: 9 | D29: =C29+2 -> 11 | E29: =D29+2 -> 13 | F29: =E29+1 -> 14 | G29: =F29+1 -> 15
B30: Penjualan Martabak Asin
B31: Martabak Telur | C31: 9 | D31: =C31+3 -> 12 | E31: =D31+2 -> 14 | F31: =E31+1 -> 15 | G31: =F31+1 -> 16
B32: Martabak Daging Ayam | C32: 8 | D32: =C32+2 -> 10 | E32: =D32+2 -> 12 | F32: =E32+2 -> 14 | G32: =F32+2 -> 16
B33: Martabak Daging Kambing | C33: 10 | D33: =C33+2 -> 12 | E33: =D33+2 -> 14 | F33: =E33+1 -> 15 | G33: =F33+2 -> 17
B34: Martabak Daging Sapi | C34: 11 | D34: =C34+2 -> 13 | E34: =D34+2 -> 15 | F34: =E34+1 -> 16 | G34: =F34+1 -> 17
B35: Penjualan Minuman
B36: Penjualan Es Jeruk | C36: 8 | D36: =C36+3 -> 11 | E36: =D36+2 -> 13 | F36: =E36+2 -> 15 | G36: =F36+1 -> 16
B37: Penjualan Es Teh Manis | C37: 10 | D37: =C37+2 -> 12 | E37: =D37+2 -> 14 | F37: =E37+2 -> 16 | G37: =F37+1 -> 17
B38: Penjualan Es Teh Tawar | C38: 12 | D38: =C38+2 -> 14 | E38: =D38+2 -> 16 | F38: =E38 -> 16 | G38: =F38+1 -> 17
B39: Penjualan Air Mineral | C39: 10 | D39: =C39+2 -> 12 | E39: =D39+1 -> 13 | F39: =E39+1 -> 14 | G39: =F39 -> 14
B42: Harga Martabak naik per tahunnya | C42: Tahun 1 | D42: Tahun 2 | E42: Tahun 3 | F42: Tahun 4 | G42: Tahun 5
B43: Martabak Small
B44: Harga | C44: 15000 | D44: =C47 -> 15000 | E44: =D47 -> 17000 | F44: =E47 -> 20000 | G44: =F47 -> 23000
B45: Kenaikan Harga | D45: 0.1 | E45: 0.12 | F45: 0.13 | G45: 0.15
...

Sheet Sheet3
B3: Initial Outlay
B4: Aktiva Tetap | C4: =Sheet1!C14 -> 148510000
B5: Biaya Sewa | C5: =Sheet1!C15 -> 40000000
B6: Biaya Amdal | C6: =Sheet1!C16 -> 325000
B7: Biaya Survey | C7: =Sheet1!C17 -> 750000
B8: Biaya Iklan | C8: =Sheet1!C18 -> 1000000
B9: Total | C9: =SUM(C4:C8) -> 190585000
B12: Tahun | C12: Laba
B13: 1 | C13: =Sheet1!D10 -> 467412000
B14: 2 | C14: =Sheet1!E10 -> 761526600
B15: 3 | C15: =Sheet1!F10 -> 1100799648
B16: 4 | C16: =Sheet1!G10 -> 1.4344721e+09
B17: 5 | C17: =Sheet1!H10 -> 1.8725587e+09
B19: Oppurtinity Cost | C19: 0.2
B21: Investasi disebut layak jika
B22: Payback period | C22: <3 Tahun
B23: Internal Rate of Return | C23: >20%
B24: Profitability Index | C24: > 1.2
B26: NPV
B27: Tahun | C27: Cashflow | D27: PV
B28: 0 | C28: =-C9 -> -190585000 | D28: =PV($C$19,B28,,-C28,) -> -190585000
B29: 1 | C29: =C13 -> 467412000 | D29: =PV($C$19,B29,,-C29,) -> 389510000
B30: 2 | C30: =C14 -> 761526600 | D30: =PV($C$19,B30,,-C30,) -> 5.2883792e+08
B31: 3 | C31: =C15 -> 1100799648 | D31: =PV($C$19,B31,,-C31,) -> 6.3703683e+08
B32: 4 | C32: =C16 -> 1.4344721e+09 | D32: =PV($C$19,B32,,-C32,) -> 6.9177858e+08
B33: 5 | C33: =C17 -> 1.8725587e+09 | D33: =PV($C$19,B33,,-C33,) -> 7.5253934e+08
B34: NPV | D34: =SUM(D28:D33) -> 2.8091177e+09
B36: IRR
B37: Tahun | C37: Cashflow
B38: 0 | C38: =C28 -> -190585000
B39: 1 | C39: =C29 -> 467412000
B40: 2 | C40: =C30 -> 761526600
B41: 3 | C41: =C31 -> 1100799648
B42: 4 | C42: =C32 -> 1.4344721e+09
B43: 5 | C43: =C33 -> 1.8725587e+09
B44: IRR | C44: =IRR(C38:C43) -> 2.9797695
B46: Payback Period
B47: Tahun | C47: Cashflow | D47: Akumulasi | E47: Payback Period
B48: 0 | C48: =C38 -> -190585000 | D48: =C48 -> -190585000
B49: 1 | C49: =C39 -> 467412000 | D49: =D48+C49 -> 276827000 | E49: =D48/(C49/12) -> -4.8929424
...
